<?xml version="1.0"?>
<robot name="my_diff_drive_robot">

 
  
  <!-- ==================== LINKS (Fiziksel Parçalar) ==================== -->

  <!-- 1. Chassis (Ana Gövde) -->
  <link name="base_link">
    <visual>
      <origin xyz="0 0 0" rpy="0 0 0"/>
      <geometry>
        <box size="0.3 0.2 0.1"/> <!-- Uzunluk, Genişlik, Yükseklik -->
      </geometry>
      <material name="blue">
        <color rgba="0 0 0.8 1"/>
      </material>
    </visual>
    <collision>
      <origin xyz="0 0 0" rpy="0 0 0"/>
      <geometry>
        <box size="0.3 0.2 0.1"/>
      </geometry>
      <surface>
            <friction>
              <ode>
                <mu>0.8</mu>
                <mu2>0.8</mu2>
              </ode>
            </friction>
      </surface>
    </collision>
    <inertial>
      <origin xyz="0 0 0" rpy="0 0 0"/>
      <mass value="5.0"/> <!-- 5 kg -->
      <inertia ixx="0.05" ixy="0" ixz="0" iyy="0.08" iyz="0" izz="0.1"/>
    </inertial>
  </link>
  
  <gazebo reference="base_link">
    <material>Gazebo/Blue</material> <!-- Opsiyonel: Gazebo'da farklı bir renk atar -->
    <kinematic>false</kinematic>
    <self_collide>false</self_collide>
  </gazebo>

  <!-- 2. Left Wheel (Sol Tekerlek) -->
  <link name="left_wheel_link">
    <visual>
      <origin xyz="0 0 0" rpy="1.570795 0 0"/> <!-- Tekerleği dikey çevir -->
      <geometry>
        <cylinder radius="0.05" length="0.02"/> <!-- Yarıçap, Kalınlık -->
      </geometry>
      <material name="black">
        <color rgba="0 0 0 1"/>
      </material>
    </visual>
    <collision>
      <origin xyz="0 0 0" rpy="1.570795 0 0"/>
      <geometry>
        <cylinder radius="0.05" length="0.02"/>
      </geometry>
      <surface>
            <friction>
              <ode>
                <mu>1.0</mu>    <!-- Statik sürtünme katsayısı -->
                <mu2>1.0</mu2>   <!-- Dinamik sürtünme katsayısı -->
              </ode>
            </friction>
      </surface>
    </collision>
    <inertial>
      <origin xyz="0 0 0" rpy="0 0 0"/>
      <mass value="0.1"/>
      <inertia ixx="0.0001" ixy="0" ixz="0" iyy="0.0001" iyz="0" izz="0.0001"/>
    </inertial>
  </link>
  
<gazebo reference="left_wheel_link">
    <mu1>1.0</mu1>
    <mu2>1.0</mu2>
    <kp>1000000.0</kp>
    <kd>100.0</kd>
    <minDepth>0.001</minDepth>
    <maxVel>0.1</maxVel>
    <fdir1>1 0 0</fdir1>
    <material>Gazebo/Black</material>
  </gazebo>

  <!-- 3. Right Wheel (Sağ Tekerlek) -->
  <link name="right_wheel_link">
    <visual>
      <origin xyz="0 0 0" rpy="1.570795 0 0"/>
      <geometry>
        <cylinder radius="0.05" length="0.02"/>
      </geometry>
      <material name="black"/>
    </visual>
    <collision>
      <origin xyz="0 0 0" rpy="1.570795 0 0"/>
      <geometry>
        <cylinder radius="0.05" length="0.02"/>
      </geometry>
      <surface>
            <friction>
              <ode>
                <mu>1.0</mu>    <!-- Statik sürtünme katsayısı -->
                <mu2>1.0</mu2>   <!-- Dinamik sürtünme katsayısı -->
              </ode>
            </friction>
       </surface>
    </collision>
    <inertial>
      <origin xyz="0 0 0" rpy="0 0 0"/>
      <mass value="0.1"/>
      <inertia ixx="0.0001" ixy="0" ixz="0" iyy="0.0001" iyz="0" izz="0.0001"/>
    </inertial>
  </link>
  
 <gazebo reference="right_wheel_link">
    <mu1>1.0</mu1>
    <mu2>1.0</mu2>
    <kp>1000000.0</kp>
    <kd>100.0</kd>
    <minDepth>0.001</minDepth>
    <maxVel>0.1</maxVel>
    <fdir1>1 0 0</fdir1>
    <material>Gazebo/Black</material>
  </gazebo>

  <!-- 4. Caster Wheel (Döner Tekerlek) -->
  <link name="caster_wheel_link">
    <visual>
      <origin xyz="0 0 0" rpy="0 0 0"/>
      <geometry>
        <sphere radius="0.03"/> <!-- Yarıçap -->
      </geometry>
      <material name="grey">
        <color rgba="0.7 0.7 0.7 1"/>
      </material>
    </visual>
    <collision>
      <origin xyz="0 0 0" rpy="0 0 0"/>
      <geometry>
        <sphere radius="0.03"/>
      </geometry>
      <surface>
            <friction>
              <ode>
                <mu>1.0</mu>    <!-- Statik sürtünme katsayısı -->
                <mu2>1.0</mu2>   <!-- Dinamik sürtünme katsayısı -->
              </ode>
            </friction>
      </surface>
    </collision>
    <inertial>
      <origin xyz="0 0 0" rpy="0 0 0"/>
      <mass value="0.05"/>
      <inertia ixx="0.00005" ixy="0" ixz="0" iyy="0.00005" iyz="0" izz="0.00005"/>
    </inertial>
  </link>
  
      
<!-- ==================== CAMERA ==================== -->
      
      <!-- 1. Camera Link (Fiziksel Parça) -->
      <link name="camera_link">
        <visual>
          <origin xyz="0 0 0" rpy="0 -1.570795 -1.570795"/>
          <geometry>
            <box size="0.02 0.05 0.05"/> <!-- Küçük bir kutu olarak görselleştirelim -->
          </geometry>
          <material name="red">
            <color rgba="1 0 0 1"/>
          </material>
        </visual>
        <collision>
          <origin xyz="0 0 0" rpy="0 0 0"/>
          <geometry>
            <box size="0.02 0.05 0.05"/>
          </geometry>
        </collision>
        <inertial>
          <origin xyz="0 0 0" rpy="0 0 0"/>
          <mass value="0.01"/>
          <inertia ixx="1e-6" ixy="0" ixz="0" iyy="1e-6" iyz="0" izz="1e-6"/>
        </inertial>
      </link>
     
   

 

  <!-- ==================== JOINTS (Bağlantılar) ==================== -->

  <!-- Sol Tekerlek Eklemi -->
  <joint name="left_wheel_joint" type="continuous">
    <parent link="base_link"/>
    <child link="left_wheel_link"/>
    <origin xyz="0 -0.11 -0.025" rpy="0 0 0"/> <!-- Chassis'in solunda, biraz aşağıda -->
    <axis xyz="0 1 0"/> <!-- Y ekseni etrafında döner (tekerlek dönme ekseni) -->
    <limit effort="1.0" velocity="1.0"/>
  </joint>

  <!-- Sağ Tekerlek Eklemi -->
  <joint name="right_wheel_joint" type="continuous">
    <parent link="base_link"/>
    <child link="right_wheel_link"/>
    <origin xyz="0 0.11 -0.025" rpy="0 0 0"/> <!-- Chassis'in sağında, biraz aşağıda -->
    <axis xyz="0 1 0"/>
    <limit effort="1.0" velocity="1.0"/>
  </joint>

  <!-- Döner Tekerlek Eklemi -->
  <joint name="caster_wheel_joint" type="fixed">
    <parent link="base_link"/>
    <child link="caster_wheel_link"/>
    <origin xyz="0.12 0 -0.045" rpy="0 0 0"/> <!-- Chassis'in önünde, zemine daha yakın -->
    <!-- Caster wheel'ın kendi içinde dönme ekseni olsa da, chassis'e göre konumu sabittir. -->
    <!-- Bu yüzden 'fixed' tipinde tanımlıyoruz. İç mekanizması simülasyon motoru tarafından halledilir. -->
  </joint>
  
        <!-- Camera Joint (Bağlantı) -->
   <joint name="camera_joint" type="fixed">
        <parent link="base_link"/>
        <child link="camera_link"/>
        <origin xyz="0.15 0 0.075" rpy="0 0 0"/> <!-- base_link'in önünde (x=0.15) ve üstünde (z=0.075) -->
   </joint>
      
<!-- ==================== GAZEBO CAMERA SENSOR ==================== -->     
<gazebo reference="camera_link">
  <sensor name="camera_sensor" type="camera">
    <camera>
      <horizontal_fov>1.047</horizontal_fov>
      <image>
        <width>640</width>
        <height>480</height>
      </image>
      <clip>
        <near>0.1</near>
        <far>100</far>
      </clip>
    </camera>
    <always_on>1</always_on>
    <update_rate>30</update_rate>
    <visualize>true</visualize>
    <topic>/camera/image_raw</topic>
  </sensor>
</gazebo>

      
<!-- DIFF DRIVE PLUGIN -->
<gazebo>
  <plugin
    filename="libgz-sim-diff-drive-system.so"
    name="gz::sim::systems::DiffDrive">
    <left_joint>left_wheel_joint</left_joint>
    <right_joint>right_wheel_joint</right_joint>
    <wheel_separation>0.22</wheel_separation>
    <wheel_radius>0.05</wheel_radius>
    <topic>/cmd_vel</topic>
    <odom_topic>/odom</odom_topic>
    <tf_topic>/tf</tf_topic>
    <frame_id>odom</frame_id>
    <child_frame_id>base_link</child_frame_id>
    <publish_odom>true</publish_odom>
    <publish_odom_tf>true</publish_odom_tf>
  </plugin>
</gazebo>

<!-- JOINT STATE PUBLISHER PLUGIN -->
<!-- Gazebo'dan ROS'a joint_states yayınlar (tekerleklerin açısal pozisyonları) -->
<gazebo>
  <plugin
    filename="libgz-sim-joint-state-publisher-system.so"
    name="gz::sim::systems::JointStatePublisher">
    <topic>joint_states</topic>
    <update_rate>50</update_rate>
  </plugin>
</gazebo>
      
      

  <!-- ==================== MATERIALS (Renkler) ==================== -->
  <material name="blue">
    <color rgba="0 0 0.8 1"/>
  </material>
  <material name="black">
    <color rgba="0 0 0 1"/>
  </material>
  <material name="grey">
    <color rgba="0.7 0.7 0.7 1"/>
  </material>
  <material name="red">
        <color rgba="1 0 0 1"/>
  </material>

</robot>
